<?xml version="1.0" ?>
<robot name="bot" xmlns:xacro="http://www.ros.org/wiki/xacro">
    <link name="base_footprint"/>
    
    <link name="base_link">
        <inertial>
            <origin xyz="0 0 0" rpy="0 0 0"/>
            <mass value="5.0"/>
            <inertia ixx="0.1" ixy="0.0" ixz="0.0" iyy="0.1" iyz="0.0" izz="0.1"/>
        </inertial>
        <visual>
            <origin xyz="0.0 0.0 0.0" rpy="0.0 0.0 0.0"/>
            <geometry>
                <box size="0.7 0.5 0.2"/>
            </geometry>
            <material name="red">
                <color rgba="1.0 0.0 0.0 1.0"/>
            </material>
        </visual>
        <collision>
            <origin xyz="0.0 0.0 0.0" rpy="0.0 0.0 0.0"/>
            <geometry>
                <box size="0.7 0.5 0.2"/>
            </geometry>
        </collision>
    </link>
    
    <joint name="base_joint" type="fixed">
        <origin xyz="0.0 0.0 0.15" rpy="0.0 0.0 0.0"/>
        <parent link="base_footprint"/>
        <child link="base_link"/>
    </joint>

    <!-- Right Wheel -->
    <link name="right_wheel_link">
    <inertial>
        <origin xyz="0 0 0" rpy="0 0 0"/>
        <mass value="1.0"/>
        <inertia ixx="0.01" ixy="0.0" ixz="0.0" iyy="0.01" iyz="0.0" izz="0.01"/>
    </inertial>
    <visual>
        <origin xyz="0.0 0.0 0.0" rpy="0.0 0.0 0.0"/>
        <geometry>
        <cylinder radius="0.15" length="0.05"/>
        </geometry>
        <material name="blue">
        <color rgba="0.0 0.0 1.0 1.0"/>
        </material>
    </visual>
    <collision>
        <origin xyz="0.0 0.0 0.0" rpy="0.0 0.0 0.0"/>
        <geometry>
        <cylinder radius="0.15" length="0.05"/>
        </geometry>
    </collision>
    </link>

    <joint name="right_wheel_joint" type="continuous">
        <origin xyz="0.0 -0.275 0.0" rpy="1.57 0.0 0.0"/>
        <parent link="base_link"/>
        <child link="right_wheel_link"/>
        <axis xyz="0.0 0.0 -1.0"/>
    </joint>


    <!-- Left Wheel -->
    <link name="left_wheel_link">
    <inertial>
        <origin xyz="0 0 0" rpy="0 0 0"/>
        <mass value="1.0"/>
        <inertia ixx="0.01" ixy="0.0" ixz="0.0" iyy="0.01" iyz="0.0" izz="0.01"/>
    </inertial>
    <visual>
        <origin xyz="0.0 0.0 0.0" rpy="0.0 0.0 0.0"/>
        <geometry>
        <cylinder radius="0.15" length="0.05"/>
        </geometry>
        <material name="blue">
        <color rgba="0.0 0.0 1.0 1.0"/>
        </material>
    </visual>
    <collision>
        <origin xyz="0.0 0.0 0.0" rpy="0.0 0.0 0.0"/>
        <geometry>
        <cylinder radius="0.15" length="0.05"/>
        </geometry>
    </collision>
    </link>

    <joint name="left_wheel_joint" type="continuous">
        <origin xyz="0.0 0.275 0.0" rpy="1.57 0.0 0.0"/>
        <parent link="base_link"/>
        <child link="left_wheel_link"/>
        <axis xyz="0.0 0.0 -1.0"/>
    </joint>

    <!-- Front Castor -->
    <link name="front_castor_link">
    <inertial>
        <origin xyz="0 0 0" rpy="0 0 0"/>
        <mass value="0.5"/>
        <inertia ixx="0.005" ixy="0.0" ixz="0.0" iyy="0.005" iyz="0.0" izz="0.005"/>
    </inertial>
    <visual>
        <origin xyz="0.0 0.0 0.0" rpy="0.0 0.0 0.0"/>
        <geometry>
        <sphere radius="0.045"/>
        </geometry>
        <material name="black">
        <color rgba="0.0 0.0 0.0 1.0"/>
        </material>
    </visual>
    <collision>
        <origin xyz="0.0 0.0 0.0" rpy="0.0 0.0 0.0"/>
        <geometry>
        <sphere radius="0.045"/>
        </geometry>
    </collision>
    </link>

    <joint name="front_castor_joint" type="fixed">
        <origin xyz="0.25 0.0 -0.1" rpy="0.0 0.0 0.0"/>
        <parent link="base_link"/>
        <child link="front_castor_link"/>
    </joint>

    <!-- Rear Castor -->
    <link name="back_castor_link">
    <inertial>
        <origin xyz="0 0 0" rpy="0 0 0"/>
        <mass value="0.5"/>
        <inertia ixx="0.005" ixy="0.0" ixz="0.0" iyy="0.005" iyz="0.0" izz="0.005"/>
    </inertial>
    <visual>
        <origin xyz="0.0 0.0 0.0" rpy="0.0 0.0 0.0"/>
        <geometry>
        <sphere radius="0.045"/>
        </geometry>
        <material name="black">
        <color rgba="0.0 0.0 0.0 1.0"/>
        </material>
    </visual>
    <collision>
        <origin xyz="0.0 0.0 0.0" rpy="0.0 0.0 0.0"/>
        <geometry>
        <sphere radius="0.045"/>
        </geometry>
    </collision>
    </link>

    <joint name="back_castor_joint" type="fixed">
        <origin xyz="-0.25 0.0 -0.1" rpy="0.0 0.0 0.0"/>
        <parent link="base_link"/>
        <child link="back_castor_link"/>
    </joint>


</robot>